Workbook
Name _Toc203478608: 'Calcul Wp et Wt'!$B$28
Name _Toc203478609: 'Calcul Wp et Wt'!$B$5

Sheet Général
B10: Description du modèle d'évaluation
B12: Type de projet | C12: Station de transfert d'énergie par pompage (STEP)
B14: Nom du projet | C14: STEP EL Menzel
B16: Date | C16: 46203
B18: Auteur du modèle | C18: Office National de l'Electricité et de l'Eau potable (ONEE)
B22: Code couleur – Guide de saisie du modèle
B24: Ces cellules sont à renseigner par le soumissionnaire | C24: 100
B26: Ces cellules correspondent à des hypothèses communes à l'ensemble des soumissionnaires | C26: 100
B28: Les cellules blanches (verrouillées) sont des formules de calcul | C28: 100
B30: Les cellules bleu (verrouillées) sont des résultats | C30: 100

Sheet Inputs
B1: STEP El Menzel
B2: AO N° SP4130189
B3: Comparaison des offres commerciales
B4: Soumissionnaire :
B6: 1- Prix par devise | L6: 2- Taux de change | P6: 3- Autres hypothèses d'évaluation
B7: Montant de l'offre | G7: Montant Part en MAD | H7: Montant Part en Euro | I7: Montant Part en USD | L7: EURO/MAD | P7: Taux d'actualisation | R7: 0.0572
L8: USD/MAD | P8: Coût de pompage MAD/kWh | R8: 0.3
P9: Taux d'intérêt de l'emprunt | R9: 0.04
B11: 4- Performances énergétiques garanties
B13: 4.1- Fonctionnement en turbine | O13: 4.2- Fonctionnement en pompe
B15: Rendement hydraulique en turbine | O15: Rendement hydraulique en pompe
C16: Circuit individuel | D16: Circuits communs | P16: Circuit individuel | Q16: Circuits communs
B17: Coefficient de perte de charge hydraulique (s2/m5) | C17: k1T= | D17: k2T= | O17: Coefficient de perte de charge hydraulique (s2/m5) | P17: k1P= | Q17: k2P=
O19: s/m2
B20: Rendement turbine | O20: Rendement Pompe
B21: Note : Les pertes de charge, les puissances et les hauteurs de chute nettes, sauf dans le cas nominal où la hauteur de chute brute est considérée, sont automatiquement calculées sur la base des indices K1P et K2P indiqués, pour la situation avec un seul groupe en fonctionnement. | O21: Note : Les pertes de charge, les puissances et les hauteurs de refoulement nettes sont automatiquement calculées sur la base des indices K1P et K2P indiqués, pour la situation avec un seul groupe en fonctionnement.
G23: ηT pour Ratio P/Pt
B24: Htbrute (m) | C24: Qt (m3/s) | D24: ΔhT (m) | E24: Htnette (m) | F24: Pt (KW) | G24: 10/10 | H24: 9/10 | I24: 8/10 | J24: 7/10 | K24: 6/10 | L24: 5/10 | O24: Hpbrute (m) | P24: Qp (m3/s) | Q24: ΔhP (m) | R24: Hpnette (m) | S24: Pp (kW) | T24: ηP
B25: 286 | D25: =$C$18*C25^2+$D$18*(C25*1)^2 -> 0 | E25: =B25-D25 -> 286 | F25: =998*9.795*E25*C25/1000*G25 -> 0 | O25: 286 | Q25: =$P$18*P25^2+$Q$18*(P25*1)^2 -> 0 | R25: =O25+Q25 -> 286 | S25: =998*9.795*R25*P25/1000/T25 -> #DIV/0!
B26: 270 | D26: =$C$18*C26^2+$D$18*(C26*1)^2 -> 0 | E26: =B26-D26 -> 270 | F26: =998*9.795*E26*C26/1000*G26 -> 0 | O26: 270 | Q26: =$P$18*P26^2+$Q$18*(P26*1)^2 -> 0 | R26: =O26+Q26 -> 270 | S26: =998*9.795*R26*P26/1000/T26 -> #DIV/0!
B27: =E27+D27 -> 250.9 | C27: 80 | D27: =$C$18*C27^2+$D$18*(C27*1)^2 -> 0 | E27: 250.9 | F27: =998*9.795*E27*C27/1000*G27 -> 0 | O27: 254 | Q27: =$P$18*P27^2+$Q$18*(P27*1)^2 -> 0 | R27: =O27+Q27 -> 254 | S27: =998*9.795*R27*P27/1000/T27 -> #DIV/0!
B28: 238 | D28: =$C$18*C28^2+$D$18*(C28*1)^2 -> 0 | E28: =B28-D28 -> 238 | F28: =998*9.795*E28*C28/1000*G28 -> 0 | O28: 238 | Q28: =$P$18*P28^2+$Q$18*(P28*1)^2 -> 0 | R28: =O28+Q28 -> 238 | S28: =998*9.795*R28*P28/1000/T28 -> #DIV/0!
B29: 222 | D29: =$C$18*C29^2+$D$18*(C29*1)^2 -> 0 | E29: =B29-D29 -> 222 | F29: =998*9.795*E29*C29/1000*G29 -> 0 | O29: 222 | Q29: =$P$18*P29^2+$Q$18*(P29*1)^2 -> 0 | R29: =O29+Q29 -> 222 | S29: =998*9.795*R29*P29/1000/T29 -> #DIV/0!
B34: Rendement Alternateur | O34: Rendement Moteur
B36: Palt/ Pnalt = | C36: 10/10 | D36: 9/10 | E36: 8/10 | F36: 7/10 | G36: 6/10 | H36: 5/10 | O36: Hpbrute (m) | P36: PM (MW) | Q36: ηM1 cos ɸ=1 | R36: ηM2 cos ɸ=0,95
B37: η Alt 1 _ cos ɸ=1 | C37: ηA1 | D37: ηA2 | E37: ηA3 | F37: ηA4 | G37: ηA5 | H37: ηA6 | O37: 286
O38: 270
B39: η Alt 2 _ cos ɸ=0,85 | C39: ηA11 | D39: ηA12 | E39: ηA13 | F39: ηA14 | G39: ηA15 | H39: ηA16 | O39: 254
O40: 238
O41: 222
B44: Puissance consommée par les auxiliaires généraux essentiels (en KW) | O44: Puissance consommée par les auxiliaires directs d’un groupe (en KW)
B45: Auxiliaires généraux | G45: Puissance consommée (kW) | O45: Auxiliaires de groupe | R45: Puissance consommée (kW)
B46: Système de ventilation et climatisation (PS1) | O46: Système de regulation (PS20)
B47: Système de réfrigération (PS2) | O47: Système de drainage de la turbine-pompe (PS21)
B48: Compresseurs de procédé (PS3) | O48: Installation du freinage et du levage du rotor (PS22)
B49: Installation auxiliaire basse tension (ondulateurs statiques) (PS4) | O49: Éléments chauffants du générateur (PS23)
B50: Installation d'une alimentation en courant continu (redresseurs)(PS5) | O50: Ventilation et refroidissement du générateur (PS24)
B51: Système de dénoyage (PS6) | O51: Système d'excitation et de régulation de tension (PS25)
B52: Convertisseur de fréquence (PS7) | O52: Ventilation du transformateur MT/HT (PS26)
B53: Equipment de levage (PS8) | O53: Tableau Basse Tension du groupe (PS7)
...

Sheet Calcul du CMA du kWh
B1: STEP El Menzel
B2: =+Inputs!B2 -> AO N° SP4130189
B3: Comparaison des offres commerciales
B4: =+Inputs!B4 -> Soumissionnaire : | D4: =+Inputs!G4 -> 0
C7: Coefficients d'actualisation | D7: Energie produite WT | E7: Energie consommée Wp | F7: Annuité de remboursement du CAPEX | G7: Charges fixes d'exploitation Cfe (1,5% du MS Actualisé) | H7: Charges de pompage | I7: Charges fixes d'exploitation actualisées Cfe | J7: Charges de pompage actualisées | K7: Annuité CAPEX actualisée | L7: Charges totales actualisées en MAD | M7: Energie produite actualisée en kWh
B8: Année | C8: (1+t)^n | D8: en kWh | E8: en kWh | F8: en MAD | G8: en MAD | H8: en MAD | I8: en MAD | J8: en MAD | K8: Fₙ/(1+t)^n en MAD | M8: Wt/(1+t)^n
B9: 1 | C9: =POWER(1+Inputs!$R$7,B9) -> 1.0572 | D9: =+'Calcul Wp et Wt'!C24 -> #DIV/0! | E9: =+'Calcul Wp et Wt'!C46 -> #DIV/0! | F9: =+-PMT(Inputs!$R$9,40,Inputs!$G$79) -> 0 | G9: =Inputs!$G$79*0.015 -> 0 | H9: =+E9*Inputs!$R$8 -> #DIV/0! | I9: =+G9/C9 -> 0 | J9: =+H9/C9 -> #DIV/0! | K9: =F9/C9 -> 0 | L9: =I9+J9+K9 -> #DIV/0! | M9: =D9/C9 -> #DIV/0!
B10: =1+B9 -> 2 | C10: =POWER(1+Inputs!$R$7,B10) -> 1.1176718 | D10: =+D9 -> #DIV/0! | E10: =+E9 -> #DIV/0! | F10: =+-PMT(Inputs!$R$9,40,Inputs!$G$79) -> 0 | G10: =Inputs!$G$79*0.015 -> 0 | H10: =+E10*Inputs!$R$8 -> #DIV/0! | I10: =+G10/C10 -> 0 | J10: =+H10/C10 -> #DIV/0! | K10: =F10/C10 -> 0 | L10: =I10+J10+K10 -> #DIV/0! | M10: =D10/C10 -> #DIV/0!
B11: =1+B10 -> 3 | C11: =POWER(1+Inputs!$R$7,B11) -> 1.1816027 | D11: =+D10 -> #DIV/0! | E11: =+E10 -> #DIV/0! | F11: =+-PMT(Inputs!$R$9,40,Inputs!$G$79) -> 0 | G11: =Inputs!$G$79*0.015 -> 0 | H11: =+E11*Inputs!$R$8 -> #DIV/0! | I11: =+G11/C11 -> 0 | J11: =+H11/C11 -> #DIV/0! | K11: =F11/C11 -> 0 | L11: =I11+J11+K11 -> #DIV/0! | M11: =D11/C11 -> #DIV/0!
B12: =1+B11 -> 4 | C12: =POWER(1+Inputs!$R$7,B12) -> 1.2491903 | D12: =+D11 -> #DIV/0! | E12: =+E11 -> #DIV/0! | F12: =+-PMT(Inputs!$R$9,40,Inputs!$G$79) -> 0 | G12: =Inputs!$G$79*0.015 -> 0 | H12: =+E12*Inputs!$R$8 -> #DIV/0! | I12: =+G12/C12 -> 0 | J12: =+H12/C12 -> #DIV/0! | K12: =F12/C12 -> 0 | L12: =I12+J12+K12 -> #DIV/0! | M12: =D12/C12 -> #DIV/0!
B13: =1+B12 -> 5 | C13: =POWER(1+Inputs!$R$7,B13) -> 1.320644 | D13: =+D12 -> #DIV/0! | E13: =+E12 -> #DIV/0! | F13: =+-PMT(Inputs!$R$9,40,Inputs!$G$79) -> 0 | G13: =Inputs!$G$79*0.015 -> 0 | H13: =+E13*Inputs!$R$8 -> #DIV/0! | I13: =+G13/C13 -> 0 | J13: =+H13/C13 -> #DIV/0! | K13: =F13/C13 -> 0 | L13: =I13+J13+K13 -> #DIV/0! | M13: =D13/C13 -> #DIV/0!
B14: =1+B13 -> 6 | C14: =POWER(1+Inputs!$R$7,B14) -> 1.3961849 | D14: =+D13 -> #DIV/0! | E14: =+E13 -> #DIV/0! | F14: =+-PMT(Inputs!$R$9,40,Inputs!$G$79) -> 0 | G14: =Inputs!$G$79*0.015 -> 0 | H14: =+E14*Inputs!$R$8 -> #DIV/0! | I14: =+G14/C14 -> 0 | J14: =+H14/C14 -> #DIV/0! | K14: =F14/C14 -> 0 | L14: =I14+J14+K14 -> #DIV/0! | M14: =D14/C14 -> #DIV/0!
B15: =1+B14 -> 7 | C15: =POWER(1+Inputs!$R$7,B15) -> 1.4760466 | D15: =+D14 -> #DIV/0! | E15: =+E14 -> #DIV/0! | F15: =+-PMT(Inputs!$R$9,40,Inputs!$G$79) -> 0 | G15: =Inputs!$G$79*0.015 -> 0 | H15: =+E15*Inputs!$R$8 -> #DIV/0! | I15: =+G15/C15 -> 0 | J15: =+H15/C15 -> #DIV/0! | K15: =F15/C15 -> 0 | L15: =I15+J15+K15 -> #DIV/0! | M15: =D15/C15 -> #DIV/0!
B16: =1+B15 -> 8 | C16: =POWER(1+Inputs!$R$7,B16) -> 1.5604765 | D16: =+D15 -> #DIV/0! | E16: =+E15 -> #DIV/0! | F16: =+-PMT(Inputs!$R$9,40,Inputs!$G$79) -> 0 | G16: =Inputs!$G$79*0.015 -> 0 | H16: =+E16*Inputs!$R$8 -> #DIV/0! | I16: =+G16/C16 -> 0 | J16: =+H16/C16 -> #DIV/0! | K16: =F16/C16 -> 0 | L16: =I16+J16+K16 -> #DIV/0! | M16: =D16/C16 -> #DIV/0!
B17: =1+B16 -> 9 | C17: =POWER(1+Inputs!$R$7,B17) -> 1.6497358 | D17: =+D16 -> #DIV/0! | E17: =+E16 -> #DIV/0! | F17: =+-PMT(Inputs!$R$9,40,Inputs!$G$79) -> 0 | G17: =Inputs!$G$79*0.015 -> 0 | H17: =+E17*Inputs!$R$8 -> #DIV/0! | I17: =+G17/C17 -> 0 | J17: =+H17/C17 -> #DIV/0! | K17: =F17/C17 -> 0 | L17: =I17+J17+K17 -> #DIV/0! | M17: =D17/C17 -> #DIV/0!
B18: =1+B17 -> 10 | C18: =POWER(1+Inputs!$R$7,B18) -> 1.7441007 | D18: =+D17 -> #DIV/0! | E18: =+E17 -> #DIV/0! | F18: =+-PMT(Inputs!$R$9,40,Inputs!$G$79) -> 0 | G18: =Inputs!$G$79*0.015 -> 0 | H18: =+E18*Inputs!$R$8 -> #DIV/0! | I18: =+G18/C18 -> 0 | J18: =+H18/C18 -> #DIV/0! | K18: =F18/C18 -> 0 | L18: =I18+J18+K18 -> #DIV/0! | M18: =D18/C18 -> #DIV/0!
B19: =1+B18 -> 11 | C19: =POWER(1+Inputs!$R$7,B19) -> 1.8438632 | D19: =+D18 -> #DIV/0! | E19: =+E18 -> #DIV/0! | F19: =+-PMT(Inputs!$R$9,40,Inputs!$G$79) -> 0 | G19: =Inputs!$G$79*0.015 -> 0 | H19: =+E19*Inputs!$R$8 -> #DIV/0! | I19: =+G19/C19 -> 0 | J19: =+H19/C19 -> #DIV/0! | K19: =F19/C19 -> 0 | L19: =I19+J19+K19 -> #DIV/0! | M19: =D19/C19 -> #DIV/0!
B20: =1+B19 -> 12 | C20: =POWER(1+Inputs!$R$7,B20) -> 1.9493322 | D20: =+D19 -> #DIV/0! | E20: =+E19 -> #DIV/0! | F20: =+-PMT(Inputs!$R$9,40,Inputs!$G$79) -> 0 | G20: =Inputs!$G$79*0.015 -> 0 | H20: =+E20*Inputs!$R$8 -> #DIV/0! | I20: =+G20/C20 -> 0 | J20: =+H20/C20 -> #DIV/0! | K20: =F20/C20 -> 0 | L20: =I20+J20+K20 -> #DIV/0! | M20: =D20/C20 -> #DIV/0!
B21: =1+B20 -> 13 | C21: =POWER(1+Inputs!$R$7,B21) -> 2.060834 | D21: =+D20 -> #DIV/0! | E21: =+E20 -> #DIV/0! | F21: =+-PMT(Inputs!$R$9,40,Inputs!$G$79) -> 0 | G21: =Inputs!$G$79*0.015 -> 0 | H21: =+E21*Inputs!$R$8 -> #DIV/0! | I21: =+G21/C21 -> 0 | J21: =+H21/C21 -> #DIV/0! | K21: =F21/C21 -> 0 | L21: =I21+J21+K21 -> #DIV/0! | M21: =D21/C21 -> #DIV/0!
... B48: =1+B47 -> 40 | C48: =POWER(1+Inputs!$R$7,B48) -> 9.253077 | D48: =+D47 -> #DIV/0! | E48: =+E47 -> #DIV/0! | F48: =+-PMT(Inputs!$R$9,40,Inputs!$G$79) -> 0 | G48: =Inputs!$G$79*0.015 -> 0 | H48: =+E48*Inputs!$R$8 -> #DIV/0! | I48: =+G48/C48 -> 0 | J48: =+H48/C48 -> #DIV/0! | K48: =F48/C48 -> 0 | L48: =I48+J48+K48 -> #DIV/0! | M48: =D48/C48 -> #DIV/0!
F50: =SUM(F9:F48) -> 0 | G50: Total | I50: =SUM(I9:I48) -> 0 | J50: =SUM(J9:J48) -> #DIV/0! | K50: =SUM(K9:K48) -> 0 | L50: =SUM(L9:L48) -> #DIV/0! | M50: =SUM(M9:M48) -> #DIV/0!
G52: Cma (DH/kWh) = | H52: =$L$50/$M$50 -> #DIV/0!

Sheet Calcul Wp et Wt
B2: CALCUL ENERGIE PRODUITE (TURBINAGE) ET ENERGIE CONSOMMEE (POMPAGE)
B5: Fonctionnement en turbine
B8: CARACTERISTIQUES | C8: VALEUR
B9: Hauteur de chute brute nominale (m) : Htbrute | C9: 254
B10: Pertes de charge hydrauliques ΔhT | C10: =+'Tableaux I'!G14 -> 0
B11: Hauteur de chute nette (m) : Htnette = Htbrute - ΔhT | C11: =C9-C10 -> 254
B12: Débit par groupe (m3/s) : Qt | C12: =+Inputs!C27 -> 80
B13: Puissance hydraulique par groupe (kW) : PHT=998 x 9,795 x Qt x Htnette / 1000 | C13: =998*9.795*C12*C11/1000 -> 198636.33
B14: Rendements turbine ηTurb | C14: =+'Tableaux II'!H16 -> 0
B15: Puissance à l’arbre de la turbine (kW) : P1T= PHT x ηTurb | C15: =C13*C14 -> 0
B16: Rendement alternateur hAlt | C16: =+'Tableaux III'!J15 -> 0
B17: Puissance aux bornes alternateur P2T= P1T x hAlt | C17: =C15*C16 -> 0
B18: Puissance consommée par les auxiliaires par groupe (kW) : PS | C18: =+'Tableaux IV'!G55 -> 0
B19: Puissance P3T = P2T-PS | C19: =C17-C18 -> 0
B20: Rendement transformateur en mode turbinage : hTT | C20: =+'Tableaux V'!G18 -> #DIV/0!
B21: Puissance électrique aux bornes du transformateur (kW) : P4T = P3T x ηTT | C21: =C19*C20 -> #DIV/0!
B22: Durée annuelle de fonctionnement en mode turbinage (heures): Tt | C22: 1680
B23: Energie annuelle produite par groupe (kWh) : ET = P4T x Tt | C23: =C21*C22 -> #DIV/0!
B24: Energie annuelle produite par la STEP (kWh): WT = ET x 2 | C24: =C23*2 -> #DIV/0! | D24: Energie produite WT
B28: Fonctionnement en pompe
B30: CARACTERISTIQUES | C30: VALEUR
B31: Hauteur de refoulement brute nominale (m) : Hpbrute | C31: =Inputs!O27 -> 254
B32: Pertes de charge hydrauliques ΔhT | C32: =+'Tableaux I'!G29 -> 0
B33: Hauteur de refoulement nette (m) : Hp nette = Hp brute + ΔhP | C33: =C31+C32 -> 254
B34: Débit par groupe (m3/s): Qp | C34: =Inputs!P27 -> 0
B35: Puissance hydraulique par groupe (kW) : PHP= 998 x 9,795 x Qp x Hpnette / 1000 | C35: =998*9.795*C34*C33/1000 -> 0
B36: Rendement pompe ηPompe | C36: =+'Tableaux II'!H32 -> 0
B37: Puissance mécanique à l’arbre du groupe (kW) : P1P= PHT / ηPompe | C37: =C35/C36 -> #DIV/0!
B38: Rendement moteur ηMoteur | C38: =+'Tableaux III'!J31 -> 0
B39: Puissance électrique aux bornes du groupe (kW) : P2P = P1P/ ηMoteur | C39: =C37/C38 -> #DIV/0!
B40: Puissance consommée par les auxiliaires par groupe (kW): PS | C40: =+'Tableaux IV'!G55 -> 0
B41: P3P = P2P+PS | C41: =C39+C40 -> #DIV/0!
B42: Rendement transformateur : ηTP | C42: =+'Tableaux V'!G36 -> #DIV/0!
B43: Puissance électrique aux bornes du transformateur (kW) : P4P = P3P/ηTP | C43: =C41/C42 -> #DIV/0!
B44: Durée annuelle de fonctionnement en mode pompage (heures): Tp | C44: 2352
B45: Energie annuelle consommée par groupe (kWh) : Ep = P4P x Tp | C45: =C43*C44 -> #DIV/0!
B46: Energie annuelle consommée par la STEP (kWh): WP = EP x 2 | C46: =C45*2 -> #DIV/0! | D46: Energie Consommée Wp

Sheet Tableaux I
C1: TABLEAUX I
E3: CALCUL DE PERTES DE CHARGE EN TURBINE
F5: Circuit individuel | G5: Circuits communs
E6: Débit considéré (m3/s) | F6: 80 | G6: 160
E7: Coefficient de perte de charge hydraulique (s2/m5) | F7: k1T = | G7: k2T=
F8: =+Inputs!C18 -> 0 | G8: =+Inputs!D18 -> 0
D12: Pertes de charge hydrauliques ΔhT
E14: ΔhT = k1T x Qt2 + k2T x QTotal2 | G14: =F8*F6^2+G8*G6^2 -> 0
E17: CALCUL DE PERTES DE CHARGE EN POMPE
F20: Circuit individuel | G20: Circuits communs
E21: Débit considéré (m3/s) | F21: =Inputs!P27 -> 0 | G21: =F21*2 -> 0
E22: Perte de charge hydraulique | F22: k1P = | G22: k2P =
F23: =Inputs!P18 -> 0 | G23: =Inputs!Q18 -> 0
D27: Pertes de charge hydrauliques ΔhP
E29: ΔhP = k1P x Qp2 + k2P x QpTotal2 | G29: =F23*F21^2+G23*G21^2 -> 0

Sheet Tableaux II
A1: TABLEAUX II
H2: CALCUL DE RENDEMENT TURBINE
H4: ηT pour Ratio P/Pt
C5: Htbrute (m) | D5: Qt (m3/s) | E5: ΔhT (m) | F5: Htnette (m) | G5: Pt (MW) | H5: 10/10 | I5: 9/10 | J5: 8/10 | K5: 7/10 | L5: 6/10 | M5: 5/10
C6: 286 | D6: =Inputs!C25 -> 0 | E6: =Inputs!D25 -> 0 | F6: =Inputs!E25 -> 286 | G6: =Inputs!F25 -> 0 | H6: =+Inputs!G25 -> 0 | I6: =+Inputs!H25 -> 0 | J6: =+Inputs!I25 -> 0 | K6: =+Inputs!J25 -> 0 | L6: =+Inputs!K25 -> 0 | M6: =+Inputs!L25 -> 0
C7: 270 | D7: =Inputs!C26 -> 0 | E7: =Inputs!D26 -> 0 | F7: =Inputs!E26 -> 270 | G7: =Inputs!F26 -> 0 | H7: =+Inputs!G26 -> 0 | I7: =+Inputs!H26 -> 0 | J7: =+Inputs!I26 -> 0 | K7: =+Inputs!J26 -> 0 | L7: =+Inputs!K26 -> 0 | M7: =+Inputs!L26 -> 0
C8: =Inputs!B27 -> 250.9 | D8: =Inputs!C27 -> 80 | E8: =Inputs!D27 -> 0 | F8: =Inputs!E27 -> 250.9 | G8: =Inputs!F27 -> 0 | H8: =+Inputs!G27 -> 0 | I8: =+Inputs!H27 -> 0 | J8: =+Inputs!I27 -> 0 | K8: =+Inputs!J27 -> 0 | L8: =+Inputs!K27 -> 0 | M8: =+Inputs!L27 -> 0
C9: 238 | D9: =Inputs!C28 -> 0 | E9: =Inputs!D28 -> 0 | F9: =Inputs!E28 -> 238 | G9: =Inputs!F28 -> 0 | H9: =+Inputs!G28 -> 0 | I9: =+Inputs!H28 -> 0 | J9: =+Inputs!I28 -> 0 | K9: =+Inputs!J28 -> 0 | L9: =+Inputs!K28 -> 0 | M9: =+Inputs!L28 -> 0
C10: 222 | D10: =Inputs!C29 -> 0 | E10: =Inputs!D29 -> 0 | F10: =Inputs!E29 -> 222 | G10: =Inputs!F29 -> 0 | H10: =+Inputs!G29 -> 0 | I10: =+Inputs!H29 -> 0 | J10: =+Inputs!I29 -> 0 | K10: =+Inputs!J29 -> 0 | L10: =+Inputs!K29 -> 0 | M10: =+Inputs!L29 -> 0
H11: ηT1 | I11: ηT2 | J11: ηT3 | K11: ηT4 | L11: ηT5 | M11: ηT6
G12: ηT moyen = ΣηT / 5 | H12: =+(H6+H7+H8+H9+H10)/5 -> 0 | I12: =+(I6+I7+I8+I9+I10)/5 -> 0 | J12: =+(J6+J7+J8+J9+J10)/5 -> 0 | K12: =+(K6+K7+K8+K9+K10)/5 -> 0 | L12: =+(L6+L7+L8+L9+L10)/5 -> 0 | M12: =+(M6+M7+M8+M9+M10)/5 -> 0
B15: Rendement moyen pondéré en turbine :
H16: =(30*H12+30*I12+20*J12+10*K12+5*L12+5*M12)/100 -> 0
H20: CALCUL DE RENDEMENT POMPE
C23: Hpbrute (m) | D23: Qp (m3/s) | E23: ΔhP (m) | F23: Hpnette (m) | G23: Pp (MW) | H23: ηP
C24: 286 | D24: =+Inputs!P25 -> 0 | E24: =+Inputs!Q25 -> 0 | F24: =+Inputs!R25 -> 286 | G24: =+Inputs!S25 -> #DIV/0! | H24: =+Inputs!T25 -> 0
C25: 270 | D25: =+Inputs!P26 -> 0 | E25: =+Inputs!Q26 -> 0 | F25: =+Inputs!R26 -> 270 | G25: =+Inputs!S26 -> #DIV/0! | H25: =+Inputs!T26 -> 0
C26: 254 | D26: =+Inputs!P27 -> 0 | E26: =+Inputs!Q27 -> 0 | F26: =+Inputs!R27 -> 254 | G26: =+Inputs!S27 -> #DIV/0! | H26: =+Inputs!T27 -> 0
C27: 238 | D27: =+Inputs!P28 -> 0 | E27: =+Inputs!Q28 -> 0 | F27: =+Inputs!R28 -> 238 | G27: =+Inputs!S28 -> #DIV/0! | H27: =+Inputs!T28 -> 0
C28: 222 | D28: =+Inputs!P29 -> 0 | E28: =+Inputs!Q29 -> 0 | F28: =+Inputs!R29 -> 222 | G28: =+Inputs!S29 -> #DIV/0! | H28: =+Inputs!T29 -> 0
B31: Rendement moyen pondéré en pompe :
H32: =(H24+H25+H26+H27+H28)/5 -> 0

Sheet Tableaux III
E1: TABLEAUX III
G3: CALCUL DE RENDEMENT ALTERNATEUR
F5: Palt/ Pnalt = | G5: 10/10 | H5: 0.9 | I5: 8/10 | J5: 0.7 | K5: 6/10 | L5: 5/10
F6: η Alt 1 _ cos ɸ=1 | G6: ηA1 | H6: ηA2 | I6: ηA3 | J6: ηA4 | K6: ηA5 | L6: ηA6
G7: =Inputs!C38 -> 0 | H7: =Inputs!D38 -> 0 | I7: =Inputs!E38 -> 0 | J7: =Inputs!F38 -> 0 | K7: =Inputs!G38 -> 0 | L7: =Inputs!H38 -> 0
F8: η Alt 2 _ cos ɸ=0,85 | G8: ηA11 | H8: ηA12 | I8: ηA13 | J8: ηA14 | K8: ηA15 | L8: ηA16
G9: =Inputs!C40 -> 0 | H9: =Inputs!D40 -> 0 | I9: =Inputs!E40 -> 0 | J9: =Inputs!F40 -> 0 | K9: =Inputs!G40 -> 0 | L9: =Inputs!H40 -> 0
E11: ηAlt1 = (30 x ηA1+ 30 x ηA2 + 20 x ηA3 + 10 x ηA4 + 5 x ηA5 + 5 x ηA6)/100 | J11: =(30*G7+30*H7+20*I7+10*J7+5*K7+5*L7)/100 -> 0
E12: ηAlt2 = (30 x ηA11+ 30 x ηA12 + 20 x ηA13 + 10 x ηA14 + 5 x ηA15 + 5 x ηA16)/100 | J12: =(30*G9+30*H9+20*I9+10*J9+5*K9+5*L9)/100 -> 0
E14: Rendement moyen pondéré de l'alternateur :
F15: ηAlternateur = (ηAP1 + ηAP2)/2 | J15: =(J11+J12)/2 -> 0
G19: CALCUL DE RENDEMENT MOTEUR
F22: Hpbrute (m) | G22: PM (MW) | H22: ηM1 cos ɸ=1 | I22: ηM2 cos ɸ=0,95
F23: 286 | G23: =Inputs!P37 -> 0 | H23: =Inputs!Q37 -> 0 | I23: =Inputs!R37 -> 0
F24: 270 | G24: =Inputs!P38 -> 0 | H24: =Inputs!Q38 -> 0 | I24: =Inputs!R38 -> 0
F25: 254 | G25: =Inputs!P39 -> 0 | H25: =Inputs!Q39 -> 0 | I25: =Inputs!R39 -> 0
F26: 238 | G26: =Inputs!P40 -> 0 | H26: =Inputs!Q40 -> 0 | I26: =Inputs!R40 -> 0
F27: 222 | G27: =Inputs!P41 -> 0 | H27: =Inputs!Q41 -> 0 | I27: =Inputs!R41 -> 0
E30: Rendement moyen pondéré du moteur :
F31: ηMoteur = (ΣηM1+ΣηM2)/10 | J31: =(SUM(H23:H27)+SUM(I23:I27))/10 -> 0

Sheet Tableaux IV
B1: TABLEAUX IV
F3: PUISSANCE CONSOMMÉE PAR LES AUXILIAIRES GÉNÉRAUX (EN KW)
F6: Auxiliaires généraux | G6: Puissance consommée (kW)
F7: Système de ventilation et climatisation (PS1) | G7: =Inputs!G46 -> 0
F8: Système de réfrigération (PS2) | G8: =Inputs!G47 -> 0
F9: Compresseurs de procédé (PS3) | G9: =Inputs!G48 -> 0
F10: Installation auxiliaire basse tension (ondulateurs statiques) (PS4) | G10: =Inputs!G49 -> 0
F11: Installation d'une alimentation en courant continu (redresseurs)(PS5) | G11: =Inputs!G50 -> 0
F12: Système de dénoyage (PS6) | G12: =Inputs!G51 -> 0
F13: Convertisseur de fréquence (PS7) | G13: =Inputs!G52 -> 0
F14: Equipment de levage (PS8) | G14: =Inputs!G53 -> 0
F15: Equipment de protection contre les incendies (PS9) | G15: =Inputs!G54 -> 0
F16: Equipment de pompage (PS10) | G16: =Inputs!G55 -> 0
F17: Equipment hydromecanique (PS11) | G17: =Inputs!G56 -> 0
F18: Total (PSU = Σ (PS1 à PS11)) | G18: =SUM(G7:G17) -> 0
F19: Total par Groupe PSG1 = fu1*fs1*PSU *(0,4+0,6/n) | G19: =G21*G22*G18*(0.4+0.6/G23) -> 0
F21: fu1 = | G21: =Inputs!C58 -> 0.9
F22: fs1 = | G22: =Inputs!C59 -> 0.7
F23: n (groupes) = | G23: =Inputs!C60 -> 2
F34: PUISSANCE CONSOMMÉE PAR LES AUXILIAIRES DIRECTS D’UN GROUPE (EN KW)
F37: Auxiliaires de groupe : | G37: Puissance consommée (kW)
F38: Système de regulation (PS20) | G38: =Inputs!R46 -> 0
F39: Système de drainage de la turbine-pompe (PS21) | G39: =Inputs!R47 -> 0
F40: Installation du freinage et du levage du rotor (PS22) | G40: =Inputs!R48 -> 0
F41: Éléments chauffants du générateur (PS23) | G41: =Inputs!R49 -> 0
F42: Ventilation et refroidissement du générateur (PS24) | G42: =Inputs!R50 -> 0
F43: Système d'excitation et de régulation de tension (PS25) | G43: =Inputs!R51 -> 0
F44: Ventilation du transformateur MT/HT (PS26) | G44: =Inputs!R52 -> 0
F45: Tableau Basse Tension du groupe (PS7) | G45: =Inputs!R53 -> 0
F46: Total (PS = Σ (PS20 à PS26)) | G46: =SUM(G38:G45) -> 0
F47: Total par Groupe PSG2 = fu2*fs2*PS | G47: =G49*G50*G46 -> 0
F49: fu2 = | G49: =Inputs!P55 -> 0.9
F50: fs2 = | G50: =Inputs!P56 -> 0.7
F55: Puissance de soutirage en KW en pompage et en turbinage pour un groupe. PS = (PSG1 + PSG2) | G55: =G47+G19 -> 0
F57: Notes :fs=facteur de simultanéité ; fu=facteur d'utilisation

Sheet Tableaux V
A1: TABLEAUX V
D3: CALCUL DE RENDEMENT TRANSFORMATEUR EN TURBINAGE
C6: Pn_trans= | D6: =Inputs!C65 -> 0
F7: Charge (PU)
F8: 50% de Charge | G8: 75% de Charge | H8: 100% de Charge
C9: Puissance transformée (PU) (MVA) | F9: =Inputs!E68 -> 0 | G9: =Inputs!F68 -> 0 | H9: =Inputs!G68 -> 0
C10: Pertes Fer (PF) en MW | F10: =Inputs!E69 -> 0 | G10: =Inputs!F69 -> 0 | H10: =Inputs!G69 -> 0
C11: Pertes cuivre (PC) en MW | F11: =Inputs!E70 -> 0 | G11: =Inputs!F70 -> 0 | H11: =Inputs!G70 -> 0
C12: Pertes totales maximales garanties ΣP=PF+PC | F12: =F10+F11 -> 0 | G12: =G10+G11 -> 0 | H12: =H10+H11 -> 0
C13: Rendement à 75 °C : ηT = (PU- ΣP)/PU | F13: =(F9-F12)/F9 -> #DIV/0! | G13: =(G9-G12)/G9 -> #DIV/0! | H13: =(H9-H12)/H9 -> #DIV/0!
D17: Rendement moyen pondéré transformateur en turbinage:
E18: ηTT=(20 x ηT100+ 50 x ηT75+ 30 x ηT50) /100 | G18: =+(20*H13+50*G13+30*F13)/100 -> #DIV/0!
D22: CALCUL DE RENDEMENT TRANSFORMATEUR EN POMPAGE
C24: Pn_trans= | D24: =Inputs!P65 -> 0
F25: Hpbrute= | G25: Hpbrute= | H25: Hpbrute= | I25: Hpbrute= | J25: Hpbrute=
F26: 286 | G26: 270 | H26: 254 | I26: 238 | J26: 222
C27: Puissance transformée (PP) (MVA) | F27: =Inputs!R68 -> 0 | G27: =Inputs!S68 -> 0 | H27: =Inputs!T68 -> 0 | I27: =Inputs!U68 -> 0 | J27: =Inputs!V68 -> 0
C28: Pertes Fer (PF) en MW | F28: =Inputs!R69 -> 0 | G28: =Inputs!S69 -> 0 | H28: =Inputs!T69 -> 0 | I28: =Inputs!U69 -> 0 | J28: =Inputs!V69 -> 0
C29: Pertes cuivre (PC) en MW | F29: =Inputs!R70 -> 0 | G29: =Inputs!S70 -> 0 | H29: =Inputs!T70 -> 0 | I29: =Inputs!U70 -> 0 | J29: =Inputs!V70 -> 0
C30: Pertes totales maximales garanties ΣP=PF+PC | F30: =F28+F29 -> 0 | G30: =G28+G29 -> 0 | H30: =H28+H29 -> 0 | I30: =I28+I29 -> 0 | J30: =J28+J29 -> 0
C31: Rendement à 75 °C : ηT = (PP- ΣP)/PP | F31: =(F27-F30)/F27 -> #DIV/0! | G31: =(G27-G30)/G27 -> #DIV/0! | H31: =(H27-H30)/H27 -> #DIV/0! | I31: =(I27-I30)/I27 -> #DIV/0! | J31: =(J27-J30)/J27 -> #DIV/0!
D35: Rendement moyen pondéré transformateur en turbinage:
E36: ηTP=ΣηT /5 | G36: =+(SUM(F31:J31)/5) -> #DIV/0!
